2020-12-07 19:18:16,207 INFO    MainThread:27118 [internal.py:wandb_internal():62] W&B internal server running at pid: 27118
2020-12-07 19:18:16,210 INFO    WriterThread:27118 [datastore.py:open_for_write():76] open: wandb/run-20201207_191813-Data1_L1_Dist_0_M0/run-Data1_L1_Dist_0_M0.wandb
2020-12-07 19:18:16,211 DEBUG   HandlerThread:27118 [handler.py:handle_request():54] handle_request: check_version
2020-12-07 19:18:16,240 DEBUG   SenderThread:27118 [sender.py:send():89] send: header
2020-12-07 19:18:16,240 DEBUG   SenderThread:27118 [sender.py:send():89] send: request
2020-12-07 19:18:16,240 DEBUG   SenderThread:27118 [sender.py:send_request():98] send_request: check_version
2020-12-07 19:18:16,246 DEBUG   Thread-4  :27118 [connectionpool.py:_new_conn():975] Starting new HTTPS connection (1): pypi.org:443
2020-12-07 19:18:16,345 DEBUG   Thread-4  :27118 [connectionpool.py:_make_request():461] https://pypi.org:443 "GET /pypi/wandb/json HTTP/1.1" 200 52216
2020-12-07 19:18:16,381 DEBUG   SenderThread:27118 [sender.py:send():89] send: run
2020-12-07 19:18:16,418 DEBUG   SenderThread:27118 [cmd.py:execute():719] Popen(['git', 'cat-file', '--batch-check'], cwd=/home/rahulkanojia/Documents/EXP_CON/paul, universal_newlines=False, shell=None, istream=<valid stream>)
2020-12-07 19:18:16,475 DEBUG   SenderThread:27118 [connectionpool.py:_new_conn():975] Starting new HTTPS connection (1): api.wandb.ai:443
2020-12-07 19:18:16,759 DEBUG   SenderThread:27118 [connectionpool.py:_make_request():461] https://api.wandb.ai:443 "POST /graphql HTTP/1.1" 404 None
2020-12-07 19:18:16,762 ERROR   SenderThread:27118 [internal_api.py:execute():131] 404 response executing GraphQL.
2020-12-07 19:18:16,763 ERROR   SenderThread:27118 [internal_api.py:execute():132] {"errors":[{"message":"project not found","path":["upsertBucket"]}],"data":{"upsertBucket":null}}
2020-12-07 19:18:17,382 INFO    WriterThread:27118 [datastore.py:close():257] close: wandb/run-20201207_191813-Data1_L1_Dist_0_M0/run-Data1_L1_Dist_0_M0.wandb
2020-12-07 19:18:17,382 INFO    HandlerThread:27118 [handler.py:finish():267] shutting down handler
2020-12-07 19:18:17,384 ERROR   MainThread:27118 [internal.py:wandb_internal():128] Thread SenderThread:
Traceback (most recent call last):
  File "/home/rahulkanojia/envs/tf/lib/python3.7/site-packages/wandb/old/retry.py", line 96, in __call__
    result = self._call_fn(*args, **kwargs)
  File "/home/rahulkanojia/envs/tf/lib/python3.7/site-packages/wandb/internal/internal_api.py", line 134, in execute
    six.reraise(*sys.exc_info())
  File "/home/rahulkanojia/envs/tf/lib/python3.7/site-packages/six.py", line 703, in reraise
    raise value
  File "/home/rahulkanojia/envs/tf/lib/python3.7/site-packages/wandb/internal/internal_api.py", line 128, in execute
    return self.client.execute(*args, **kwargs)
  File "/home/rahulkanojia/envs/tf/lib/python3.7/site-packages/wandb/vendor/gql-0.2.0/gql/client.py", line 52, in execute
    result = self._get_result(document, *args, **kwargs)
  File "/home/rahulkanojia/envs/tf/lib/python3.7/site-packages/wandb/vendor/gql-0.2.0/gql/client.py", line 60, in _get_result
    return self.transport.execute(document, *args, **kwargs)
  File "/home/rahulkanojia/envs/tf/lib/python3.7/site-packages/wandb/vendor/gql-0.2.0/gql/transport/requests.py", line 39, in execute
    request.raise_for_status()
  File "/home/rahulkanojia/envs/tf/lib/python3.7/site-packages/requests/models.py", line 943, in raise_for_status
    raise HTTPError(http_error_msg, response=self)
requests.exceptions.HTTPError: 404 Client Error: Not Found for url: https://api.wandb.ai/graphql

During handling of the above exception, another exception occurred:

Traceback (most recent call last):
  File "/home/rahulkanojia/envs/tf/lib/python3.7/site-packages/wandb/apis/normalize.py", line 24, in wrapper
    return func(*args, **kwargs)
  File "/home/rahulkanojia/envs/tf/lib/python3.7/site-packages/wandb/internal/internal_api.py", line 974, in upsert_run
    response = self.gql(mutation, variable_values=variable_values, **kwargs)
  File "/home/rahulkanojia/envs/tf/lib/python3.7/site-packages/wandb/old/retry.py", line 105, in __call__
    if not check_retry_fn(e):
  File "/home/rahulkanojia/envs/tf/lib/python3.7/site-packages/wandb/util.py", line 602, in no_retry_auth
    raise CommError("Permission denied, ask the project owner to grant you access")
wandb.errors.error.CommError: Permission denied, ask the project owner to grant you access

During handling of the above exception, another exception occurred:

Traceback (most recent call last):
  File "/home/rahulkanojia/envs/tf/lib/python3.7/site-packages/wandb/internal/internal_util.py", line 33, in run
    self._run()
  File "/home/rahulkanojia/envs/tf/lib/python3.7/site-packages/wandb/internal/internal_util.py", line 60, in _run
    self._process(record)
  File "/home/rahulkanojia/envs/tf/lib/python3.7/site-packages/wandb/internal/internal.py", line 232, in _process
    self._sm.send(record)
  File "/home/rahulkanojia/envs/tf/lib/python3.7/site-packages/wandb/internal/sender.py", line 91, in send
    send_handler(record)
  File "/home/rahulkanojia/envs/tf/lib/python3.7/site-packages/wandb/internal/sender.py", line 378, in send_run
    self._init_run(run, config_dict)
  File "/home/rahulkanojia/envs/tf/lib/python3.7/site-packages/wandb/internal/sender.py", line 414, in _init_run
    commit=repo.last_commit,
  File "/home/rahulkanojia/envs/tf/lib/python3.7/site-packages/wandb/apis/normalize.py", line 62, in wrapper
    six.reraise(CommError, CommError(message, err), sys.exc_info()[2])
  File "/home/rahulkanojia/envs/tf/lib/python3.7/site-packages/six.py", line 702, in reraise
    raise value.with_traceback(tb)
  File "/home/rahulkanojia/envs/tf/lib/python3.7/site-packages/wandb/apis/normalize.py", line 24, in wrapper
    return func(*args, **kwargs)
  File "/home/rahulkanojia/envs/tf/lib/python3.7/site-packages/wandb/internal/internal_api.py", line 974, in upsert_run
    response = self.gql(mutation, variable_values=variable_values, **kwargs)
  File "/home/rahulkanojia/envs/tf/lib/python3.7/site-packages/wandb/old/retry.py", line 105, in __call__
    if not check_retry_fn(e):
  File "/home/rahulkanojia/envs/tf/lib/python3.7/site-packages/wandb/util.py", line 602, in no_retry_auth
    raise CommError("Permission denied, ask the project owner to grant you access")
wandb.errors.error.CommError: Permission denied, ask the project owner to grant you access
2020-12-07 19:18:17,446 DEBUG   raven-sentry.BackgroundWorker:27118 [connectionpool.py:_new_conn():975] Starting new HTTPS connection (1): o151352.ingest.sentry.io:443
2020-12-07 19:18:18,556 DEBUG   raven-sentry.BackgroundWorker:27118 [connectionpool.py:_make_request():461] https://o151352.ingest.sentry.io:443 "POST /api/5288891/store/ HTTP/1.1" 200 41
2020-12-07 19:18:19,444 INFO    MainThread:27118 [internal.py:handle_exit():137] Internal process exited
