2020-12-07 19:11:55,127 INFO    MainThread:26669 [internal.py:wandb_internal():63] W&B internal server running at pid: 26669
2020-12-07 19:11:55,131 INFO    WriterThread:26669 [datastore.py:open_for_write():76] open: /home/rahulkanojia/Documents/EXP_CON/paul/Experiments/wandb/run-20201207_191152-Data1_L1_Dist_0_M0/run-Data1_L1_Dist_0_M0.wandb
2020-12-07 19:11:55,131 DEBUG   HandlerThread:26669 [handler.py:handle_request():55] handle_request: check_version
2020-12-07 19:11:55,134 DEBUG   SenderThread:26669 [sender.py:send():90] send: header
2020-12-07 19:11:55,134 DEBUG   SenderThread:26669 [sender.py:send():90] send: request
2020-12-07 19:11:55,134 DEBUG   SenderThread:26669 [sender.py:send_request():99] send_request: check_version
2020-12-07 19:11:55,140 DEBUG   Thread-4  :26669 [connectionpool.py:_new_conn():975] Starting new HTTPS connection (1): pypi.org:443
2020-12-07 19:11:55,240 DEBUG   Thread-4  :26669 [connectionpool.py:_make_request():461] https://pypi.org:443 "GET /pypi/wandb/json HTTP/1.1" 200 52216
2020-12-07 19:11:55,274 DEBUG   SenderThread:26669 [sender.py:send():90] send: run
2020-12-07 19:11:55,320 DEBUG   SenderThread:26669 [cmd.py:execute():719] Popen(['git', 'cat-file', '--batch-check'], cwd=/home/rahulkanojia/Documents/EXP_CON/paul, universal_newlines=False, shell=None, istream=<valid stream>)
2020-12-07 19:11:55,400 DEBUG   SenderThread:26669 [connectionpool.py:_new_conn():975] Starting new HTTPS connection (1): api.wandb.ai:443
2020-12-07 19:11:55,704 DEBUG   SenderThread:26669 [connectionpool.py:_make_request():461] https://api.wandb.ai:443 "POST /graphql HTTP/1.1" 404 None
2020-12-07 19:11:55,707 ERROR   SenderThread:26669 [internal_api.py:execute():133] 404 response executing GraphQL.
2020-12-07 19:11:55,707 ERROR   SenderThread:26669 [internal_api.py:execute():134] {"errors":[{"message":"project not found","path":["upsertBucket"]}],"data":{"upsertBucket":null}}
2020-12-07 19:11:56,274 INFO    WriterThread:26669 [datastore.py:close():257] close: /home/rahulkanojia/Documents/EXP_CON/paul/Experiments/wandb/run-20201207_191152-Data1_L1_Dist_0_M0/run-Data1_L1_Dist_0_M0.wandb
2020-12-07 19:11:56,275 INFO    HandlerThread:26669 [handler.py:finish():271] shutting down handler
2020-12-07 19:11:56,823 ERROR   MainThread:26669 [internal.py:wandb_internal():129] Thread SenderThread:
Traceback (most recent call last):
  File "/home/rahulkanojia/envs/tf/lib/python3.7/site-packages/wandb/old/retry.py", line 96, in __call__
    result = self._call_fn(*args, **kwargs)
  File "/home/rahulkanojia/envs/tf/lib/python3.7/site-packages/wandb/sdk/internal/internal_api.py", line 136, in execute
    six.reraise(*sys.exc_info())
  File "/home/rahulkanojia/envs/tf/lib/python3.7/site-packages/six.py", line 703, in reraise
    raise value
  File "/home/rahulkanojia/envs/tf/lib/python3.7/site-packages/wandb/sdk/internal/internal_api.py", line 130, in execute
    return self.client.execute(*args, **kwargs)
  File "/home/rahulkanojia/envs/tf/lib/python3.7/site-packages/wandb/vendor/gql-0.2.0/gql/client.py", line 52, in execute
    result = self._get_result(document, *args, **kwargs)
  File "/home/rahulkanojia/envs/tf/lib/python3.7/site-packages/wandb/vendor/gql-0.2.0/gql/client.py", line 60, in _get_result
    return self.transport.execute(document, *args, **kwargs)
  File "/home/rahulkanojia/envs/tf/lib/python3.7/site-packages/wandb/vendor/gql-0.2.0/gql/transport/requests.py", line 39, in execute
    request.raise_for_status()
  File "/home/rahulkanojia/envs/tf/lib/python3.7/site-packages/requests/models.py", line 943, in raise_for_status
    raise HTTPError(http_error_msg, response=self)
requests.exceptions.HTTPError: 404 Client Error: Not Found for url: https://api.wandb.ai/graphql

During handling of the above exception, another exception occurred:

Traceback (most recent call last):
  File "/home/rahulkanojia/envs/tf/lib/python3.7/site-packages/wandb/apis/normalize.py", line 24, in wrapper
    return func(*args, **kwargs)
  File "/home/rahulkanojia/envs/tf/lib/python3.7/site-packages/wandb/sdk/internal/internal_api.py", line 976, in upsert_run
    response = self.gql(mutation, variable_values=variable_values, **kwargs)
  File "/home/rahulkanojia/envs/tf/lib/python3.7/site-packages/wandb/old/retry.py", line 105, in __call__
    if not check_retry_fn(e):
  File "/home/rahulkanojia/envs/tf/lib/python3.7/site-packages/wandb/util.py", line 658, in no_retry_auth
    raise CommError("Permission denied, ask the project owner to grant you access")
wandb.errors.error.CommError: Permission denied, ask the project owner to grant you access

During handling of the above exception, another exception occurred:

Traceback (most recent call last):
  File "/home/rahulkanojia/envs/tf/lib/python3.7/site-packages/wandb/sdk/internal/internal_util.py", line 33, in run
    self._run()
  File "/home/rahulkanojia/envs/tf/lib/python3.7/site-packages/wandb/sdk/internal/internal_util.py", line 60, in _run
    self._process(record)
  File "/home/rahulkanojia/envs/tf/lib/python3.7/site-packages/wandb/sdk/internal/internal.py", line 233, in _process
    self._sm.send(record)
  File "/home/rahulkanojia/envs/tf/lib/python3.7/site-packages/wandb/sdk/internal/sender.py", line 92, in send
    send_handler(record)
  File "/home/rahulkanojia/envs/tf/lib/python3.7/site-packages/wandb/sdk/internal/sender.py", line 379, in send_run
    self._init_run(run, config_dict)
  File "/home/rahulkanojia/envs/tf/lib/python3.7/site-packages/wandb/sdk/internal/sender.py", line 415, in _init_run
    commit=repo.last_commit,
  File "/home/rahulkanojia/envs/tf/lib/python3.7/site-packages/wandb/apis/normalize.py", line 62, in wrapper
    six.reraise(CommError, CommError(message, err), sys.exc_info()[2])
  File "/home/rahulkanojia/envs/tf/lib/python3.7/site-packages/six.py", line 702, in reraise
    raise value.with_traceback(tb)
  File "/home/rahulkanojia/envs/tf/lib/python3.7/site-packages/wandb/apis/normalize.py", line 24, in wrapper
    return func(*args, **kwargs)
  File "/home/rahulkanojia/envs/tf/lib/python3.7/site-packages/wandb/sdk/internal/internal_api.py", line 976, in upsert_run
    response = self.gql(mutation, variable_values=variable_values, **kwargs)
  File "/home/rahulkanojia/envs/tf/lib/python3.7/site-packages/wandb/old/retry.py", line 105, in __call__
    if not check_retry_fn(e):
  File "/home/rahulkanojia/envs/tf/lib/python3.7/site-packages/wandb/util.py", line 658, in no_retry_auth
    raise CommError("Permission denied, ask the project owner to grant you access")
wandb.errors.error.CommError: Permission denied, ask the project owner to grant you access
2020-12-07 19:11:56,889 DEBUG   raven-sentry.BackgroundWorker:26669 [connectionpool.py:_new_conn():975] Starting new HTTPS connection (1): o151352.ingest.sentry.io:443
2020-12-07 19:11:57,954 DEBUG   raven-sentry.BackgroundWorker:26669 [connectionpool.py:_make_request():461] https://o151352.ingest.sentry.io:443 "POST /api/5288891/store/ HTTP/1.1" 200 41
2020-12-07 19:11:58,887 INFO    MainThread:26669 [internal.py:handle_exit():138] Internal process exited
